Workbook

Sheet Annahmen
A1: TÆLLA · Read Layer · SOMNIO — Ertragsmodell (Stand 24.10.2026, CFO)
A2: Blau = änderbare Eingabe, gelb hinterlegt = Szenario-Treiber, schwarz = Formel. Monat 1 = 01/2027, 24 Monate. Alle Beträge in EUR netto, sofern nicht anders angegeben. Szenarien: B = vorsichtig, C = mittel, D = stark.
A4: Treiber | B4: vorsichtig | C4: mittel | D4: stark | E4: Einheit | F4: Quelle / Begründung
A6: ALLGEMEIN
A7: Wechselkurs EUR/USD | B7: 1.1193 | E7: USD je EUR | F7: EZB-Referenzkurs 23.10.2026, ecb.europa.eu
A8: MwSt App-Abo/Patenschaft (B2C) | B8: 0.19 | E8: Anteil | F8: Annahme Regelsatz – Steuerberater prüfen
A9: MwSt E-Book/Hörbuch (SOMNIO) | B9: 0.07 | E9: Anteil | F9: Annahme ermäßigter Satz elektronische Publikationen – Steuerberater prüfen
A10: Kalk. Stundensatz manuelle Prüfung | B10: 60 | E10: €/h | F10: Vorschlag CFO (Grundlage Schnitt-Aufschlag)
A12: KOSTENBASIS (aus Projektdokumenten, USD)
A13: Text EN+DE (DeepSeek, Stages 200–420) | B13: 0.09 | E13: $/1.000 Wörter | F13: TECHNIK.md Abschn. 2; PROJEKTSTAND 11.10.
A14: Basis-Audio Chatterbox (Modal L4) | B14: 0.94 | E14: $/Audio-h | F14: TECHNIK.md; PROJEKTSTAND 15.10. (2,48 $ / 2,65 h)
A15: Premium-Audio Gemini ab 01.01.2027 | B15: 1.62 | E15: $/Audio-h | F15: TECHNIK.md (0,81 $ × 2 ab 2027)
A16: Wortzeiten MMS_FA (Modal) | B16: =0.034/(13.4/60) -> 0.15223881 | E16: $/Audio-h | F16: PIPELINE.md Smoke Lauf 5: Stage 520 0,0340 $ für 13,4 Audio-min
A17: Hörspiel-VC Chatterbox | B17: 0.5 | E17: $/Werk | F17: TECHNIK.md; PROJEKTSTAND 14.10.
A18: Hörspiel Sprecherzuordnung 57b (DeepSeek Pro) | B18: 1 | E18: $/Werk | F18: PROJEKTSTAND 12.10. (~1 $/Roman)
A19: Hörspiel Trennungsmessung (Modal T4) | B19: 0.03 | E19: $/Werk | F19: PROJEKTSTAND 16.10.
A20: Text einsprachig (Import/Tagging 200+210) | B20: =(0.0031+0.0021)/1.339 -> 0.0038834951 | E20: $/1.000 Wörter | F20: PIPELINE.md Smoke Lauf 5 (1.339 Wörter)
A21: Wörter je Audio-Stunde | B21: 9300 | E21: Wörter/h | F21: ACX: ~9.300 Wörter je fertiger Stunde (acx.com); Smoke-Kalibrierung unten
A22: Ø Wörter je Katalogwerk (PD) | B22: =18600000/187 -> 99465.241 | E22: Wörter | F22: PROJEKTSTAND: 187 Werke / 18,6 Mio. Wörter
A23: Ø Wörter je Verlagstitel | B23: 80000 | E23: Wörter | F23: Pilot-Obergrenze AP_cockpit_v2
A24: Wörter je Normseite (1.800 Zeichen) | B24: 250 | E24: Wörter | F24: Annahme CFO
A26: SMOKE-TEST-KALIBRIERUNG (Lauf 5, 24.10.2026)
A27: Wörter Smoke-Werk (EN) | B27: 1339 | E27: Wörter | F27: PIPELINE.md
A28: Textkosten gesamt | B28: 0.0685 | E28: $ | F28: PIPELINE.md
A29: Modal gesamt (500+520) | B29: 0.1574 | E29: $ | F29: PIPELINE.md
A30: Audio-Minuten EN+DE | B30: 13.4 | E30: min | F30: PIPELINE.md (2 × 6,7 min)
A31: → Text je 1.000 Wörter (gemessen) | B31: =$B$28/$B$27*1000 -> 0.05115758 | E31: $/1.000 W | F31: liegt unter Ansatz 0,09 $ (Ansatz bleibt, konservativ)
A32: → Modal je Audio-h (gemessen, roh) | B32: =$B$29/($B$30/60) -> 0.70477612 | E32: $/Audio-h | F32: vgl. Ansatz 0,94 + Wortzeiten
A33: → Wörter je Audio-h Chatterbox roh / nach Tempo 0,73 | B33: =$B$27/(6.7/60)*0.73 -> 8753.4627 | E33: Wörter/h | F33: PROJEKTSTAND 15.10. atempo 0,73
A35: KOSTEN JE WERK (Ø Katalogwerk, EN+DE, in EUR)
A36: Audio-Stunden je Sprache | B36: =$B$22/$B$21 -> 10.695187 | E36: h | F36: Formel
A37: Text EN+DE | B37: =$B$22/1000*$B$13/$B$7 -> 7.9977411 | E37: €/Werk | F37: Formel
A38: Basis-Audio EN+DE (Chatterbox) | B38: =2*$B$36*$B$14/$B$7 -> 17.963863 | E38: €/Werk | F38: Formel
A39: Wortzeiten EN+DE | B39: =2*$B$36*$B$16/$B$7 -> 2.9093586 | E39: €/Werk | F39: Formel
A40: Premium-Audio EN+DE (Gemini 2027) | B40: =2*$B$36*$B$15/$B$7 -> 30.958998 | E40: €/Werk | F40: Formel
A41: Hörspiel-Schicht (VC + 57b + Messung) | B41: =($B$17+$B$18+$B$19)/$B$7 -> 1.3669258 | E41: €/Werk | F41: Formel
A42: → Katalogwerk Basis (Text + Basis-Audio + Wortzeiten) | B42: =$B$37+$B$38+$B$39 -> 28.870963 | E42: €/Werk | F42: TÆLLA-Katalog / SOMNIO
A43: → Zusatz Premium-Hörbuch (Gemini statt Chatterbox) | B43: =$B$40 -> 30.958998 | E43: €/Werk | F43: Patenschaft Hörbuch
A44: → Zusatz Hörspiel (Premium + Schicht) | B44: =$B$40+$B$41 -> 32.325924 | E44: €/Werk | F44: Patenschaft Hörspiel / Auftrag
A45: Verlagstitel: BFSG-EPUB ohne Audio | B45: =$B$23/1000*$B$20/$B$7 -> 0.27756599 | E45: €/Titel | F45: Formel
...

Sheet TÆLLA
A1: TÆLLA App (B2C) — 24 Monate ab 01/2027
A3: Kennzahl | B3: ="vorsichtig – "&Annahmen!$B$133 -> vorsichtig – teures Hobby | C3: ="mittel – "&Annahmen!$C$133 -> mittel – profitabler Nebenerwerb | D3: ="stark – "&Annahmen!$D$133 -> stark – skalierbares Business
A4: Break-even monatlich (erster Monat Ergebnis > 0) | B4: =IFERROR("Monat "&MATCH(1,AA18:AA41,0)&" ("&INDEX($B$18:$B$41,MATCH(1,AA18:AA41,0))&")","nicht in 24 M") -> nicht in 24 M | C4: =IFERROR("Monat "&MATCH(1,AA47:AA70,0)&" ("&INDEX($B$47:$B$70,MATCH(1,AA47:AA70,0))&")","nicht in 24 M") -> Monat 16 (04/2028) | D4: =IFERROR("Monat "&MATCH(1,AA76:AA99,0)&" ("&INDEX($B$76:$B$99,MATCH(1,AA76:AA99,0))&")","nicht in 24 M") -> Monat 12 (12/2027)
A5: Break-even kumuliert (erster Monat kum. ≥ 0) | B5: =IFERROR("Monat "&MATCH(1,AB18:AB41,0)&" ("&INDEX($B$18:$B$41,MATCH(1,AB18:AB41,0))&")","nicht in 24 M") -> nicht in 24 M | C5: =IFERROR("Monat "&MATCH(1,AB47:AB70,0)&" ("&INDEX($B$47:$B$70,MATCH(1,AB47:AB70,0))&")","nicht in 24 M") -> nicht in 24 M | D5: =IFERROR("Monat "&MATCH(1,AB76:AB99,0)&" ("&INDEX($B$76:$B$99,MATCH(1,AB76:AB99,0))&")","nicht in 24 M") -> Monat 19 (07/2028)
A6: Deckungsbeitrag (netto, nach Gebühren)
A7: DB je Hörbuch-Zahler/Monat – Stripe | B7: =Annahmen!$B$78/(1+Annahmen!$B$8)*(1-Annahmen!$B$75)-Annahmen!$B$76*(Annahmen!$B$61+(1-Annahmen!$B$61)/12) -> 4.5308162 | C7: =Annahmen!$C$78/(1+Annahmen!$B$8)*(1-Annahmen!$B$75)-Annahmen!$B$76*(Annahmen!$C$61+(1-Annahmen!$C$61)/12) -> 4.4717185 | D7: =Annahmen!$D$78/(1+Annahmen!$B$8)*(1-Annahmen!$B$75)-Annahmen!$B$76*(Annahmen!$D$61+(1-Annahmen!$D$61)/12) -> 4.4126208
A8: DB je Hörbuch-Zahler/Monat – App-Store | B8: =Annahmen!$B$78/(1+Annahmen!$B$8)*(1-Annahmen!$B$74) -> 4.06625 | C8: =Annahmen!$C$78/(1+Annahmen!$B$8)*(1-Annahmen!$B$74) -> 3.9954762 | D8: =Annahmen!$D$78/(1+Annahmen!$B$8)*(1-Annahmen!$B$74) -> 3.9247024
A9: DB je Vollzugang-Zahler/Monat – Stripe | B9: =Annahmen!$B$79/(1+Annahmen!$B$8)*(1-Annahmen!$B$75)-Annahmen!$B$76*(Annahmen!$B$61+(1-Annahmen!$B$61)/12) -> 6.1035053 | C9: =Annahmen!$C$79/(1+Annahmen!$B$8)*(1-Annahmen!$B$75)-Annahmen!$B$76*(Annahmen!$C$61+(1-Annahmen!$C$61)/12) -> 6.0168165 | D9: =Annahmen!$D$79/(1+Annahmen!$B$8)*(1-Annahmen!$B$75)-Annahmen!$B$76*(Annahmen!$D$61+(1-Annahmen!$D$61)/12) -> 5.9301278
A10: DB je Vollzugang-Zahler/Monat – App-Store | B10: =Annahmen!$B$79/(1+Annahmen!$B$8)*(1-Annahmen!$B$74) -> 5.4233929 | C10: =Annahmen!$C$79/(1+Annahmen!$B$8)*(1-Annahmen!$B$74) -> 5.3288095 | D10: =Annahmen!$D$79/(1+Annahmen!$B$8)*(1-Annahmen!$B$74) -> 5.2342262
A11: DB je Patenschaft Hörbuch (Stripe) | B11: =Annahmen!$B$71/(1+Annahmen!$B$8)*(1-Annahmen!$B$75)-Annahmen!$B$76-Annahmen!$B$43 -> 18.44659 | C11: =Annahmen!$B$71/(1+Annahmen!$B$8)*(1-Annahmen!$B$75)-Annahmen!$B$76-Annahmen!$B$43 -> 18.44659 | D11: =Annahmen!$B$71/(1+Annahmen!$B$8)*(1-Annahmen!$B$75)-Annahmen!$B$76-Annahmen!$B$43 -> 18.44659
A12: DB je Patenschaft Hörspiel (Stripe) | B12: =Annahmen!$B$72/(1+Annahmen!$B$8)*(1-Annahmen!$B$75)-Annahmen!$B$76-Annahmen!$B$44 -> 29.495631 | C12: =Annahmen!$B$72/(1+Annahmen!$B$8)*(1-Annahmen!$B$75)-Annahmen!$B$76-Annahmen!$B$44 -> 29.495631 | D12: =Annahmen!$B$72/(1+Annahmen!$B$8)*(1-Annahmen!$B$75)-Annahmen!$B$76-Annahmen!$B$44 -> 29.495631
A13: Katalogkosten je Werk (Basis EN+DE) | B13: =Annahmen!$B$42 -> 28.870963 | C13: =Annahmen!$B$42 -> 28.870963 | D13: =Annahmen!$B$42 -> 28.870963
A16: ="Szenario vorsichtig – "&Annahmen!$B$133 -> Szenario vorsichtig – teures Hobby
A17: Monat | B17: Datum | C17: MAU | D17: Neu zahlend | E17: Zahlende gesamt | F17: davon Hörbuch | G17: davon Voll | H17: Abo-Umsatz brutto | I17: Paten Hörbuch | J17: Paten Hörspiel | K17: Paten-Umsatz brutto | L17: Auftrags-Hörspiele | M17: Auftrag brutto | N17: Umsatz brutto | O17: Umsatz netto | P17: Zahlungs-gebühren | Q17: Katalog-Neuwerke | R17: Katalog-kosten | S17: Produktion Paten/Auftrag | T17: Hosting variabel | U17: Fixkosten anteilig | V17: Marketing | W17: Personal-bedarf FTE | X17: Personal-kosten | Y17: Ergebnis | Z17: Ergebnis kumuliert | AA17: BE monatl. | AB17: BE kum.
A18: 1 | B18: 01/2027 | C18: =IF($A18<Annahmen!$B$54,0,Annahmen!$B$55) -> 0 | D18: =C18*Annahmen!$B$58 -> 0 | E18: =D18 -> 0 | F18: =E18*(1-Annahmen!$B$60) -> 0 | G18: =E18*Annahmen!$B$60 -> 0 | H18: =F18*Annahmen!$B$78+G18*Annahmen!$B$79 -> 0 | I18: =IF($A18>=Annahmen!$B$54,Annahmen!$B$63*(1-Annahmen!$B$64),0) -> 0 | J18: =IF($A18>=Annahmen!$B$54,Annahmen!$B$63*Annahmen!$B$64,0) -> 0 | K18: =I18*Annahmen!$B$71+J18*Annahmen!$B$72 -> 0 | L18: =IF($A18>=Annahmen!$B$54,Annahmen!$B$65,0) -> 0 | M18: =L18*Annahmen!$B$73 -> 0 | N18: =H18+K18+M18 -> 0 | O18: =N18/(1+Annahmen!$B$8) -> 0 | P18: =O18*(Annahmen!$B$62*Annahmen!$B$74+(1-Annahmen!$B$62)*Annahmen!$B$75)+(E18*Annahmen!$B$61+E18*(1-Annahmen!$B$61)/12+I18+J18+L18)*(1-Annahmen!$B$62)*Annahmen!$B$76 -> 0 | Q18: =Annahmen!$B$66 -> 4 | R18: =Q18*Annahmen!$B$42 -> 115.48385 | S18: =I18*Annahmen!$B$43+(J18+L18)*Annahmen!$B$44 -> 0 | T18: =C18*Annahmen!$B$77 -> 0 | U18: =SUMPRODUCT((((Annahmen!$C$145:$C$155="monatlich")*(Annahmen!$D$145:$D$155<=$A18))+((Annahmen!$C$145:$C$155="einmalig")*(Annahmen!$D$145:$D$155=$A18)))*Annahmen!$B$145:$B$155*Annahmen!$E$145:$E$155) -> 232.38508 | V18: =IF($A18>=Annahmen!$B$54,Annahmen!$B$134,0) -> 0 | W18: =MAX(0,(E18-Annahmen!$B$138)/Annahmen!$B$139) -> 0 | X18: =W18*Annahmen!$B$137 -> 0 | Y18: =O18-P18-R18-S18-T18-U18-V18-X18 -> -347.86893 | Z18: =Y18 -> -347.86893 | AA18: =IF(Y18>0,1,0) -> 0 | AB18: =IF(Z18>=0,1,0) -> 0
A19: 2 | B19: 02/2027 | C19: =IF($A19<Annahmen!$B$54,0,IF($A19=Annahmen!$B$54,Annahmen!$B$55,C18*(1+Annahmen!$B$56*(1-C18/Annahmen!$B$57)))) -> 0 | D19: =C19*Annahmen!$B$58 -> 0 | E19: =E18*(1-Annahmen!$B$59)+D19 -> 0 | F19: =E19*(1-Annahmen!$B$60) -> 0 | G19: =E19*Annahmen!$B$60 -> 0 | H19: =F19*Annahmen!$B$78+G19*Annahmen!$B$79 -> 0 | I19: =IF($A19>=Annahmen!$B$54,Annahmen!$B$63*(1-Annahmen!$B$64),0) -> 0 | J19: =IF($A19>=Annahmen!$B$54,Annahmen!$B$63*Annahmen!$B$64,0) -> 0 | K19: =I19*Annahmen!$B$71+J19*Annahmen!$B$72 -> 0 | L19: =IF($A19>=Annahmen!$B$54,Annahmen!$B$65,0) -> 0 | M19: =L19*Annahmen!$B$73 -> 0 | N19: =H19+K19+M19 -> 0 | O19: =N19/(1+Annahmen!$B$8) -> 0 | P19: =O19*(Annahmen!$B$62*Annahmen!$B$74+(1-Annahmen!$B$62)*Annahmen!$B$75)+(E19*Annahmen!$B$61+E19*(1-Annahmen!$B$61)/12+I19+J19+L19)*(1-Annahmen!$B$62)*Annahmen!$B$76 -> 0 | Q19: =Annahmen!$B$66 -> 4 | R19: =Q19*Annahmen!$B$42 -> 115.48385 | S19: =I19*Annahmen!$B$43+(J19+L19)*Annahmen!$B$44 -> 0 | T19: =C19*Annahmen!$B$77 -> 0 | U19: =SUMPRODUCT((((Annahmen!$C$145:$C$155="monatlich")*(Annahmen!$D$145:$D$155<=$A19))+((Annahmen!$C$145:$C$155="einmalig")*(Annahmen!$D$145:$D$155=$A19)))*Annahmen!$B$145:$B$155*Annahmen!$E$145:$E$155) -> 92.320468 | V19: =IF($A19>=Annahmen!$B$54,Annahmen!$B$134,0) -> 0 | W19: =MAX(0,(E19-Annahmen!$B$138)/Annahmen!$B$139) -> 0 | X19: =W19*Annahmen!$B$137 -> 0 | Y19: =O19-P19-R19-S19-T19-U19-V19-X19 -> -207.80432 | Z19: =Z18+Y19 -> -555.67325 | AA19: =IF(Y19>0,1,0) -> 0 | AB19: =IF(Z19>=0,1,0) -> 0
A20: 3 | B20: 03/2027 | C20: =IF($A20<Annahmen!$B$54,0,IF($A20=Annahmen!$B$54,Annahmen!$B$55,C19*(1+Annahmen!$B$56*(1-C19/Annahmen!$B$57)))) -> 0 | D20: =C20*Annahmen!$B$58 -> 0 | E20: =E19*(1-Annahmen!$B$59)+D20 -> 0 | F20: =E20*(1-Annahmen!$B$60) -> 0 | G20: =E20*Annahmen!$B$60 -> 0 | H20: =F20*Annahmen!$B$78+G20*Annahmen!$B$79 -> 0 | I20: =IF($A20>=Annahmen!$B$54,Annahmen!$B$63*(1-Annahmen!$B$64),0) -> 0 | J20: =IF($A20>=Annahmen!$B$54,Annahmen!$B$63*Annahmen!$B$64,0) -> 0 | K20: =I20*Annahmen!$B$71+J20*Annahmen!$B$72 -> 0 | L20: =IF($A20>=Annahmen!$B$54,Annahmen!$B$65,0) -> 0 | M20: =L20*Annahmen!$B$73 -> 0 | N20: =H20+K20+M20 -> 0 | O20: =N20/(1+Annahmen!$B$8) -> 0 | P20: =O20*(Annahmen!$B$62*Annahmen!$B$74+(1-Annahmen!$B$62)*Annahmen!$B$75)+(E20*Annahmen!$B$61+E20*(1-Annahmen!$B$61)/12+I20+J20+L20)*(1-Annahmen!$B$62)*Annahmen!$B$76 -> 0 | Q20: =Annahmen!$B$66 -> 4 | R20: =Q20*Annahmen!$B$42 -> 115.48385 | S20: =I20*Annahmen!$B$43+(J20+L20)*Annahmen!$B$44 -> 0 | T20: =C20*Annahmen!$B$77 -> 0 | U20: =SUMPRODUCT((((Annahmen!$C$145:$C$155="monatlich")*(Annahmen!$D$145:$D$155<=$A20))+((Annahmen!$C$145:$C$155="einmalig")*(Annahmen!$D$145:$D$155=$A20)))*Annahmen!$B$145:$B$155*Annahmen!$E$145:$E$155) -> 69.98508 | V20: =IF($A20>=Annahmen!$B$54,Annahmen!$B$134,0) -> 0 | W20: =MAX(0,(E20-Annahmen!$B$138)/Annahmen!$B$139) -> 0 | X20: =W20*Annahmen!$B$137 -> 0 | Y20: =O20-P20-R20-S20-T20-U20-V20-X20 -> -185.46893 | Z20: =Z19+Y20 -> -741.14218 | AA20: =IF(Y20>0,1,0) -> 0 | AB20: =IF(Z20>=0,1,0) -> 0
A21: 4 | B21: 04/2027 | C21: =IF($A21<Annahmen!$B$54,0,IF($A21=Annahmen!$B$54,Annahmen!$B$55,C20*(1+Annahmen!$B$56*(1-C20/Annahmen!$B$57)))) -> 200 | D21: =C21*Annahmen!$B$58 -> 1 | E21: =E20*(1-Annahmen!$B$59)+D21 -> 1 | F21: =E21*(1-Annahmen!$B$60) -> 0.7 | G21: =E21*Annahmen!$B$60 -> 0.3 | H21: =F21*Annahmen!$B$78+G21*Annahmen!$B$79 -> 6.26275 | I21: =IF($A21>=Annahmen!$B$54,Annahmen!$B$63*(1-Annahmen!$B$64),0) -> 0.35 | J21: =IF($A21>=Annahmen!$B$54,Annahmen!$B$63*Annahmen!$B$64,0) -> 0.15 | K21: =I21*Annahmen!$B$71+J21*Annahmen!$B$72 -> 32.245 | L21: =IF($A21>=Annahmen!$B$54,Annahmen!$B$65,0) -> 0 | M21: =L21*Annahmen!$B$73 -> 0 | N21: =H21+K21+M21 -> 38.50775 | O21: =N21/(1+Annahmen!$B$8) -> 32.359454 | P21: =O21*(Annahmen!$B$62*Annahmen!$B$74+(1-Annahmen!$B$62)*Annahmen!$B$75)+(E21*Annahmen!$B$61+E21*(1-Annahmen!$B$61)/12+I21+J21+L21)*(1-Annahmen!$B$62)*Annahmen!$B$76 -> 3.2290076 | Q21: =Annahmen!$B$66 -> 4 | R21: =Q21*Annahmen!$B$42 -> 115.48385 | S21: =I21*Annahmen!$B$43+(J21+L21)*Annahmen!$B$44 -> 15.684538 | T21: =C21*Annahmen!$B$77 -> 2 | U21: =SUMPRODUCT((((Annahmen!$C$145:$C$155="monatlich")*(Annahmen!$D$145:$D$155<=$A21))+((Annahmen!$C$145:$C$155="einmalig")*(Annahmen!$D$145:$D$155=$A21)))*Annahmen!$B$145:$B$155*Annahmen!$E$145:$E$155) -> 69.98508 | V21: =IF($A21>=Annahmen!$B$54,Annahmen!$B$134,0) -> 200 | W21: =MAX(0,(E21-Annahmen!$B$138)/Annahmen!$B$139) -> 0 | X21: =W21*Annahmen!$B$137 -> 0 | Y21: =O21-P21-R21-S21-T21-U21-V21-X21 -> -374.02302 | Z21: =Z20+Y21 -> -1115.1652 | AA21: =IF(Y21>0,1,0) -> 0 | AB21: =IF(Z21>=0,1,0) -> 0
A22: 5 | B22: 05/2027 | C22: =IF($A22<Annahmen!$B$54,0,IF($A22=Annahmen!$B$54,Annahmen!$B$55,C21*(1+Annahmen!$B$56*(1-C21/Annahmen!$B$57)))) -> 215.936 | D22: =C22*Annahmen!$B$58 -> 1.07968 | E22: =E21*(1-Annahmen!$B$59)+D22 -> 1.99968 | F22: =E22*(1-Annahmen!$B$60) -> 1.399776 | G22: =E22*Annahmen!$B$60 -> 0.599904 | H22: =F22*Annahmen!$B$78+G22*Annahmen!$B$79 -> 12.523496 | I22: =IF($A22>=Annahmen!$B$54,Annahmen!$B$63*(1-Annahmen!$B$64),0) -> 0.35 | J22: =IF($A22>=Annahmen!$B$54,Annahmen!$B$63*Annahmen!$B$64,0) -> 0.15 | K22: =I22*Annahmen!$B$71+J22*Annahmen!$B$72 -> 32.245 | L22: =IF($A22>=Annahmen!$B$54,Annahmen!$B$65,0) -> 0 | M22: =L22*Annahmen!$B$73 -> 0 | N22: =H22+K22+M22 -> 44.768496 | O22: =N22/(1+Annahmen!$B$8) -> 37.620585 | P22: =O22*(Annahmen!$B$62*Annahmen!$B$74+(1-Annahmen!$B$62)*Annahmen!$B$75)+(E22*Annahmen!$B$61+E22*(1-Annahmen!$B$61)/12+I22+J22+L22)*(1-Annahmen!$B$62)*Annahmen!$B$76 -> 3.8065529 | Q22: =Annahmen!$B$66 -> 4 | R22: =Q22*Annahmen!$B$42 -> 115.48385 | S22: =I22*Annahmen!$B$43+(J22+L22)*Annahmen!$B$44 -> 15.684538 | T22: =C22*Annahmen!$B$77 -> 2.15936 | U22: =SUMPRODUCT((((Annahmen!$C$145:$C$155="monatlich")*(Annahmen!$D$145:$D$155<=$A22))+((Annahmen!$C$145:$C$155="einmalig")*(Annahmen!$D$145:$D$155=$A22)))*Annahmen!$B$145:$B$155*Annahmen!$E$145:$E$155) -> 309.98508 | V22: =IF($A22>=Annahmen!$B$54,Annahmen!$B$134,0) -> 200 | W22: =MAX(0,(E22-Annahmen!$B$138)/Annahmen!$B$139) -> 0 | X22: =W22*Annahmen!$B$137 -> 0 | Y22: =O22-P22-R22-S22-T22-U22-V22-X22 -> -609.4988 | Z22: =Z21+Y22 -> -1724.664 | AA22: =IF(Y22>0,1,0) -> 0 | AB22: =IF(Z22>=0,1,0) -> 0
A23: 6 | B23: 06/2027 | C23: =IF($A23<Annahmen!$B$54,0,IF($A23=Annahmen!$B$54,Annahmen!$B$55,C22*(1+Annahmen!$B$56*(1-C22/Annahmen!$B$57)))) -> 233.13627 | D23: =C23*Annahmen!$B$58 -> 1.1656814 | E23: =E22*(1-Annahmen!$B$59)+D23 -> 3.005387 | F23: =E23*(1-Annahmen!$B$60) -> 2.1037709 | G23: =E23*Annahmen!$B$60 -> 0.90161609 | H23: =F23*Annahmen!$B$78+G23*Annahmen!$B$79 -> 18.821987 | I23: =IF($A23>=Annahmen!$B$54,Annahmen!$B$63*(1-Annahmen!$B$64),0) -> 0.35 | J23: =IF($A23>=Annahmen!$B$54,Annahmen!$B$63*Annahmen!$B$64,0) -> 0.15 | K23: =I23*Annahmen!$B$71+J23*Annahmen!$B$72 -> 32.245 | L23: =IF($A23>=Annahmen!$B$54,Annahmen!$B$65,0) -> 0 | M23: =L23*Annahmen!$B$73 -> 0 | N23: =H23+K23+M23 -> 51.066987 | O23: =N23/(1+Annahmen!$B$8) -> 42.913435 | P23: =O23*(Annahmen!$B$62*Annahmen!$B$74+(1-Annahmen!$B$62)*Annahmen!$B$75)+(E23*Annahmen!$B$61+E23*(1-Annahmen!$B$61)/12+I23+J23+L23)*(1-Annahmen!$B$62)*Annahmen!$B$76 -> 4.3875803 | Q23: =Annahmen!$B$66 -> 4 | R23: =Q23*Annahmen!$B$42 -> 115.48385 | S23: =I23*Annahmen!$B$43+(J23+L23)*Annahmen!$B$44 -> 15.684538 | T23: =C23*Annahmen!$B$77 -> 2.3313627 | U23: =SUMPRODUCT((((Annahmen!$C$145:$C$155="monatlich")*(Annahmen!$D$145:$D$155<=$A23))+((Annahmen!$C$145:$C$155="einmalig")*(Annahmen!$D$145:$D$155=$A23)))*Annahmen!$B$145:$B$155*Annahmen!$E$145:$E$155) -> 69.98508 | V23: =IF($A23>=Annahmen!$B$54,Annahmen!$B$134,0) -> 200 | W23: =MAX(0,(E23-Annahmen!$B$138)/Annahmen!$B$139) -> 0 | X23: =W23*Annahmen!$B$137 -> 0 | Y23: =O23-P23-R23-S23-T23-U23-V23-X23 -> -364.95898 | Z23: =Z22+Y23 -> -2089.623 | AA23: =IF(Y23>0,1,0) -> 0 | AB23: =IF(Z23>=0,1,0) -> 0
A24: 7 | B24: 07/2027 | C24: =IF($A24<Annahmen!$B$54,0,IF($A24=Annahmen!$B$54,Annahmen!$B$55,C23*(1+Annahmen!$B$56*(1-C23/Annahmen!$B$57)))) -> 251.70021 | D24: =C24*Annahmen!$B$58 -> 1.2585011 | E24: =E23*(1-Annahmen!$B$59)+D24 -> 4.0234571 | F24: =E24*(1-Annahmen!$B$60) -> 2.81642 | G24: =E24*Annahmen!$B$60 -> 1.2070371 | H24: =F24*Annahmen!$B$78+G24*Annahmen!$B$79 -> 25.197906 | I24: =IF($A24>=Annahmen!$B$54,Annahmen!$B$63*(1-Annahmen!$B$64),0) -> 0.35 | J24: =IF($A24>=Annahmen!$B$54,Annahmen!$B$63*Annahmen!$B$64,0) -> 0.15 | K24: =I24*Annahmen!$B$71+J24*Annahmen!$B$72 -> 32.245 | L24: =IF($A24>=Annahmen!$B$54,Annahmen!$B$65,0) -> 0 | M24: =L24*Annahmen!$B$73 -> 0 | N24: =H24+K24+M24 -> 57.442906 | O24: =N24/(1+Annahmen!$B$8) -> 48.271349 | P24: =O24*(Annahmen!$B$62*Annahmen!$B$74+(1-Annahmen!$B$62)*Annahmen!$B$75)+(E24*Annahmen!$B$61+E24*(1-Annahmen!$B$61)/12+I24+J24+L24)*(1-Annahmen!$B$62)*Annahmen!$B$76 -> 4.9757502 | Q24: =Annahmen!$B$66 -> 4 | R24: =Q24*Annahmen!$B$42 -> 115.48385 | S24: =I24*Annahmen!$B$43+(J24+L24)*Annahmen!$B$44 -> 15.684538 | T24: =C24*Annahmen!$B$77 -> 2.5170021 | U24: =SUMPRODUCT((((Annahmen!$C$145:$C$155="monatlich")*(Annahmen!$D$145:$D$155<=$A24))+((Annahmen!$C$145:$C$155="einmalig")*(Annahmen!$D$145:$D$155=$A24)))*Annahmen!$B$145:$B$155*Annahmen!$E$145:$E$155) -> 69.98508 | V24: =IF($A24>=Annahmen!$B$54,Annahmen!$B$134,0) -> 200 | W24: =MAX(0,(E24-Annahmen!$B$138)/Annahmen!$B$139) -> 0 | X24: =W24*Annahmen!$B$137 -> 0 | Y24: =O24-P24-R24-S24-T24-U24-V24-X24 -> -360.37487 | Z24: =Z23+Y24 -> -2449.9978 | AA24: =IF(Y24>0,1,0) -> 0 | AB24: =IF(Z24>=0,1,0) -> 0
A25: 8 | B25: 08/2027 | C25: =IF($A25<Annahmen!$B$54,0,IF($A25=Annahmen!$B$54,Annahmen!$B$55,C24*(1+Annahmen!$B$56*(1-C24/Annahmen!$B$57)))) -> 271.73486 | D25: =C25*Annahmen!$B$58 -> 1.3586743 | E25: =E24*(1-Annahmen!$B$59)+D25 -> 5.0602548 | F25: =E25*(1-Annahmen!$B$60) -> 3.5421784 | G25: =E25*Annahmen!$B$60 -> 1.5180765 | H25: =F25*Annahmen!$B$78+G25*Annahmen!$B$79 -> 31.691111 | I25: =IF($A25>=Annahmen!$B$54,Annahmen!$B$63*(1-Annahmen!$B$64),0) -> 0.35 | J25: =IF($A25>=Annahmen!$B$54,Annahmen!$B$63*Annahmen!$B$64,0) -> 0.15 | K25: =I25*Annahmen!$B$71+J25*Annahmen!$B$72 -> 32.245 | L25: =IF($A25>=Annahmen!$B$54,Annahmen!$B$65,0) -> 0 | M25: =L25*Annahmen!$B$73 -> 0 | N25: =H25+K25+M25 -> 63.936111 | O25: =N25/(1+Annahmen!$B$8) -> 53.727824 | P25: =O25*(Annahmen!$B$62*Annahmen!$B$74+(1-Annahmen!$B$62)*Annahmen!$B$75)+(E25*Annahmen!$B$61+E25*(1-Annahmen!$B$61)/12+I25+J25+L25)*(1-Annahmen!$B$62)*Annahmen!$B$76 -> 5.5747396 | Q25: =Annahmen!$B$66 -> 4 | R25: =Q25*Annahmen!$B$42 -> 115.48385 | S25: =I25*Annahmen!$B$43+(J25+L25)*Annahmen!$B$44 -> 15.684538 | T25: =C25*Annahmen!$B$77 -> 2.7173486 | U25: =SUMPRODUCT((((Annahmen!$C$145:$C$155="monatlich")*(Annahmen!$D$145:$D$155<=$A25))+((Annahmen!$C$145:$C$155="einmalig")*(Annahmen!$D$145:$D$155=$A25)))*Annahmen!$B$145:$B$155*Annahmen!$E$145:$E$155) -> 69.98508 | V25: =IF($A25>=Annahmen!$B$54,Annahmen!$B$134,0) -> 200 | W25: =MAX(0,(E25-Annahmen!$B$138)/Annahmen!$B$139) -> 0 | X25: =W25*Annahmen!$B$137 -> 0 | Y25: =O25-P25-R25-S25-T25-U25-V25-X25 -> -355.71773 | Z25: =Z24+Y25 -> -2805.7156 | AA25: =IF(Y25>0,1,0) -> 0 | AB25: =IF(Z25>=0,1,0) -> 0
A26: 9 | B26: 09/2027 | C26: =IF($A26<Annahmen!$B$54,0,IF($A26=Annahmen!$B$54,Annahmen!$B$55,C25*(1+Annahmen!$B$56*(1-C25/Annahmen!$B$57)))) -> 293.35551 | D26: =C26*Annahmen!$B$58 -> 1.4667776 | E26: =E25*(1-Annahmen!$B$59)+D26 -> 6.122212 | F26: =E26*(1-Annahmen!$B$60) -> 4.2855484 | G26: =E26*Annahmen!$B$60 -> 1.8366636 | H26: =F26*Annahmen!$B$78+G26*Annahmen!$B$79 -> 38.341883 | I26: =IF($A26>=Annahmen!$B$54,Annahmen!$B$63*(1-Annahmen!$B$64),0) -> 0.35 | J26: =IF($A26>=Annahmen!$B$54,Annahmen!$B$63*Annahmen!$B$64,0) -> 0.15 | K26: =I26*Annahmen!$B$71+J26*Annahmen!$B$72 -> 32.245 | L26: =IF($A26>=Annahmen!$B$54,Annahmen!$B$65,0) -> 0 | M26: =L26*Annahmen!$B$73 -> 0 | N26: =H26+K26+M26 -> 70.586883 | O26: =N26/(1+Annahmen!$B$8) -> 59.316709 | P26: =O26*(Annahmen!$B$62*Annahmen!$B$74+(1-Annahmen!$B$62)*Annahmen!$B$75)+(E26*Annahmen!$B$61+E26*(1-Annahmen!$B$61)/12+I26+J26+L26)*(1-Annahmen!$B$62)*Annahmen!$B$76 -> 6.1882644 | Q26: =Annahmen!$B$66 -> 4 | R26: =Q26*Annahmen!$B$42 -> 115.48385 | S26: =I26*Annahmen!$B$43+(J26+L26)*Annahmen!$B$44 -> 15.684538 | T26: =C26*Annahmen!$B$77 -> 2.9335551 | U26: =SUMPRODUCT((((Annahmen!$C$145:$C$155="monatlich")*(Annahmen!$D$145:$D$155<=$A26))+((Annahmen!$C$145:$C$155="einmalig")*(Annahmen!$D$145:$D$155=$A26)))*Annahmen!$B$145:$B$155*Annahmen!$E$145:$E$155) -> 69.98508 | V26: =IF($A26>=Annahmen!$B$54,Annahmen!$B$134,0) -> 200 | W26: =MAX(0,(E26-Annahmen!$B$138)/Annahmen!$B$139) -> 0 | X26: =W26*Annahmen!$B$137 -> 0 | Y26: =O26-P26-R26-S26-T26-U26-V26-X26 -> -350.95858 | Z26: =Z25+Y26 -> -3156.6742 | AA26: =IF(Y26>0,1,0) -> 0 | AB26: =IF(Z26>=0,1,0) -> 0
A27: 10 | B27: 10/2027 | C27: =IF($A27<Annahmen!$B$54,0,IF($A27=Annahmen!$B$54,Annahmen!$B$55,C26*(1+Annahmen!$B$56*(1-C26/Annahmen!$B$57)))) -> 316.68626 | D27: =C27*Annahmen!$B$58 -> 1.5834313 | E27: =E26*(1-Annahmen!$B$59)+D27 -> 7.2158663 | F27: =E27*(1-Annahmen!$B$60) -> 5.0511064 | G27: =E27*Annahmen!$B$60 -> 2.1647599 | H27: =F27*Annahmen!$B$78+G27*Annahmen!$B$79 -> 45.191167 | I27: =IF($A27>=Annahmen!$B$54,Annahmen!$B$63*(1-Annahmen!$B$64),0) -> 0.35 | J27: =IF($A27>=Annahmen!$B$54,Annahmen!$B$63*Annahmen!$B$64,0) -> 0.15 | K27: =I27*Annahmen!$B$71+J27*Annahmen!$B$72 -> 32.245 | L27: =IF($A27>=Annahmen!$B$54,Annahmen!$B$65,0) -> 0 | M27: =L27*Annahmen!$B$73 -> 0 | N27: =H27+K27+M27 -> 77.436167 | O27: =N27/(1+Annahmen!$B$8) -> 65.072409 | P27: =O27*(Annahmen!$B$62*Annahmen!$B$74+(1-Annahmen!$B$62)*Annahmen!$B$75)+(E27*Annahmen!$B$61+E27*(1-Annahmen!$B$61)/12+I27+J27+L27)*(1-Annahmen!$B$62)*Annahmen!$B$76 -> 6.8201016 | Q27: =Annahmen!$B$66 -> 4 | R27: =Q27*Annahmen!$B$42 -> 115.48385 | S27: =I27*Annahmen!$B$43+(J27+L27)*Annahmen!$B$44 -> 15.684538 | T27: =C27*Annahmen!$B$77 -> 3.1668626 | U27: =SUMPRODUCT((((Annahmen!$C$145:$C$155="monatlich")*(Annahmen!$D$145:$D$155<=$A27))+((Annahmen!$C$145:$C$155="einmalig")*(Annahmen!$D$145:$D$155=$A27)))*Annahmen!$B$145:$B$155*Annahmen!$E$145:$E$155) -> 69.98508 | V27: =IF($A27>=Annahmen!$B$54,Annahmen!$B$134,0) -> 200 | W27: =MAX(0,(E27-Annahmen!$B$138)/Annahmen!$B$139) -> 0 | X27: =W27*Annahmen!$B$137 -> 0 | Y27: =O27-P27-R27-S27-T27-U27-V27-X27 -> -346.06802 | Z27: =Z26+Y27 -> -3502.7422 | AA27: =IF(Y27>0,1,0) -> 0 | AB27: =IF(Z27>=0,1,0) -> 0
A28: 11 | B28: 11/2027 | C28: =IF($A28<Annahmen!$B$54,0,IF($A28=Annahmen!$B$54,Annahmen!$B$55,C27*(1+Annahmen!$B$56*(1-C27/Annahmen!$B$57)))) -> 341.8607 | D28: =C28*Annahmen!$B$58 -> 1.7093035 | E28: =E27*(1-Annahmen!$B$59)+D28 -> 8.3479005 | F28: =E28*(1-Annahmen!$B$60) -> 5.8435304 | G28: =E28*Annahmen!$B$60 -> 2.5043702 | H28: =F28*Annahmen!$B$78+G28*Annahmen!$B$79 -> 52.280814 | I28: =IF($A28>=Annahmen!$B$54,Annahmen!$B$63*(1-Annahmen!$B$64),0) -> 0.35 | J28: =IF($A28>=Annahmen!$B$54,Annahmen!$B$63*Annahmen!$B$64,0) -> 0.15 | K28: =I28*Annahmen!$B$71+J28*Annahmen!$B$72 -> 32.245 | L28: =IF($A28>=Annahmen!$B$54,Annahmen!$B$65,0) -> 0 | M28: =L28*Annahmen!$B$73 -> 0 | N28: =H28+K28+M28 -> 84.525814 | O28: =N28/(1+Annahmen!$B$8) -> 71.030096 | P28: =O28*(Annahmen!$B$62*Annahmen!$B$74+(1-Annahmen!$B$62)*Annahmen!$B$75)+(E28*Annahmen!$B$61+E28*(1-Annahmen!$B$61)/12+I28+J28+L28)*(1-Annahmen!$B$62)*Annahmen!$B$76 -> 7.474112 | Q28: =Annahmen!$B$66 -> 4 | R28: =Q28*Annahmen!$B$42 -> 115.48385 | S28: =I28*Annahmen!$B$43+(J28+L28)*Annahmen!$B$44 -> 15.684538 | T28: =C28*Annahmen!$B$77 -> 3.418607 | U28: =SUMPRODUCT((((Annahmen!$C$145:$C$155="monatlich")*(Annahmen!$D$145:$D$155<=$A28))+((Annahmen!$C$145:$C$155="einmalig")*(Annahmen!$D$145:$D$155=$A28)))*Annahmen!$B$145:$B$155*Annahmen!$E$145:$E$155) -> 69.98508 | V28: =IF($A28>=Annahmen!$B$54,Annahmen!$B$134,0) -> 200 | W28: =MAX(0,(E28-Annahmen!$B$138)/Annahmen!$B$139) -> 0 | X28: =W28*Annahmen!$B$137 -> 0 | Y28: =O28-P28-R28-S28-T28-U28-V28-X28 -> -341.01609 | Z28: =Z27+Y28 -> -3843.7583 | AA28: =IF(Y28>0,1,0) -> 0 | AB28: =IF(Z28>=0,1,0) -> 0
A29: 12 | B29: 12/2027 | C29: =IF($A29<Annahmen!$B$54,0,IF($A29=Annahmen!$B$54,Annahmen!$B$55,C28*(1+Annahmen!$B$56*(1-C28/Annahmen!$B$57)))) -> 369.02256 | D29: =C29*Annahmen!$B$58 -> 1.8451128 | E29: =E28*(1-Annahmen!$B$59)+D29 -> 9.5251813 | F29: =E29*(1-Annahmen!$B$60) -> 6.6676269 | G29: =E29*Annahmen!$B$60 -> 2.8575544 | H29: =F29*Annahmen!$B$78+G29*Annahmen!$B$79 -> 59.653829 | I29: =IF($A29>=Annahmen!$B$54,Annahmen!$B$63*(1-Annahmen!$B$64),0) -> 0.35 | J29: =IF($A29>=Annahmen!$B$54,Annahmen!$B$63*Annahmen!$B$64,0) -> 0.15 | K29: =I29*Annahmen!$B$71+J29*Annahmen!$B$72 -> 32.245 | L29: =IF($A29>=Annahmen!$B$54,Annahmen!$B$65,0) -> 0 | M29: =L29*Annahmen!$B$73 -> 0 | N29: =H29+K29+M29 -> 91.898829 | O29: =N29/(1+Annahmen!$B$8) -> 77.225907 | P29: =O29*(Annahmen!$B$62*Annahmen!$B$74+(1-Annahmen!$B$62)*Annahmen!$B$75)+(E29*Annahmen!$B$61+E29*(1-Annahmen!$B$61)/12+I29+J29+L29)*(1-Annahmen!$B$62)*Annahmen!$B$76 -> 8.1542627 | Q29: =Annahmen!$B$66 -> 4 | R29: =Q29*Annahmen!$B$42 -> 115.48385 | S29: =I29*Annahmen!$B$43+(J29+L29)*Annahmen!$B$44 -> 15.684538 | T29: =C29*Annahmen!$B$77 -> 3.6902256 | U29: =SUMPRODUCT((((Annahmen!$C$145:$C$155="monatlich")*(Annahmen!$D$145:$D$155<=$A29))+((Annahmen!$C$145:$C$155="einmalig")*(Annahmen!$D$145:$D$155=$A29)))*Annahmen!$B$145:$B$155*Annahmen!$E$145:$E$155) -> 69.98508 | V29: =IF($A29>=Annahmen!$B$54,Annahmen!$B$134,0) -> 200 | W29: =MAX(0,(E29-Annahmen!$B$138)/Annahmen!$B$139) -> 0 | X29: =W29*Annahmen!$B$137 -> 0 | Y29: =O29-P29-R29-S29-T29-U29-V29-X29 -> -335.77205 | Z29: =Z28+Y29 -> -4179.5303 | AA29: =IF(Y29>0,1,0) -> 0 | AB29: =IF(Z29>=0,1,0) -> 0
A30: 13 | B30: 01/2028 | C30: =IF($A30<Annahmen!$B$54,0,IF($A30=Annahmen!$B$54,Annahmen!$B$55,C29*(1+Annahmen!$B$56*(1-C29/Annahmen!$B$57)))) -> 398.32648 | D30: =C30*Annahmen!$B$58 -> 1.9916324 | E30: =E29*(1-Annahmen!$B$59)+D30 -> 10.754799 | F30: =E30*(1-Annahmen!$B$60) -> 7.5283594 | G30: =E30*Annahmen!$B$60 -> 3.2264398 | H30: =F30*Annahmen!$B$78+G30*Annahmen!$B$79 -> 67.354619 | I30: =IF($A30>=Annahmen!$B$54,Annahmen!$B$63*(1-Annahmen!$B$64),0) -> 0.35 | J30: =IF($A30>=Annahmen!$B$54,Annahmen!$B$63*Annahmen!$B$64,0) -> 0.15 | K30: =I30*Annahmen!$B$71+J30*Annahmen!$B$72 -> 32.245 | L30: =IF($A30>=Annahmen!$B$54,Annahmen!$B$65,0) -> 0 | M30: =L30*Annahmen!$B$73 -> 0 | N30: =H30+K30+M30 -> 99.599619 | O30: =N30/(1+Annahmen!$B$8) -> 83.697158 | P30: =O30*(Annahmen!$B$62*Annahmen!$B$74+(1-Annahmen!$B$62)*Annahmen!$B$75)+(E30*Annahmen!$B$61+E30*(1-Annahmen!$B$61)/12+I30+J30+L30)*(1-Annahmen!$B$62)*Annahmen!$B$76 -> 8.8646502 | Q30: =Annahmen!$B$66 -> 4 | R30: =Q30*Annahmen!$B$42 -> 115.48385 | S30: =I30*Annahmen!$B$43+(J30+L30)*Annahmen!$B$44 -> 15.684538 | T30: =C30*Annahmen!$B$77 -> 3.9832648 | U30: =SUMPRODUCT((((Annahmen!$C$145:$C$155="monatlich")*(Annahmen!$D$145:$D$155<=$A30))+((Annahmen!$C$145:$C$155="einmalig")*(Annahmen!$D$145:$D$155=$A30)))*Annahmen!$B$145:$B$155*Annahmen!$E$145:$E$155) -> 69.98508 | V30: =IF($A30>=Annahmen!$B$54,Annahmen!$B$134,0) -> 200 | W30: =MAX(0,(E30-Annahmen!$B$138)/Annahmen!$B$139) -> 0 | X30: =W30*Annahmen!$B$137 -> 0 | Y30: =O30-P30-R30-S30-T30-U30-V30-X30 -> -330.30423 | Z30: =Z29+Y30 -> -4509.8346 | AA30: =IF(Y30>0,1,0) -> 0 | AB30: =IF(Z30>=0,1,0) -> 0
... A41: 24 | B41: 12/2028 | C41: =IF($A41<Annahmen!$B$54,0,IF($A41=Annahmen!$B$54,Annahmen!$B$55,C40*(1+Annahmen!$B$56*(1-C40/Annahmen!$B$57)))) -> 919.71099 | D41: =C41*Annahmen!$B$58 -> 4.5985549 | E41: =E40*(1-Annahmen!$B$59)+D41 -> 30.113255 | F41: =E41*(1-Annahmen!$B$60) -> 21.079279 | G41: =E41*Annahmen!$B$60 -> 9.0339766 | H41: =F41*Annahmen!$B$78+G41*Annahmen!$B$79 -> 188.59179 | I41: =IF($A41>=Annahmen!$B$54,Annahmen!$B$63*(1-Annahmen!$B$64),0) -> 0.35 | J41: =IF($A41>=Annahmen!$B$54,Annahmen!$B$63*Annahmen!$B$64,0) -> 0.15 | K41: =I41*Annahmen!$B$71+J41*Annahmen!$B$72 -> 32.245 | L41: =IF($A41>=Annahmen!$B$54,Annahmen!$B$65,0) -> 0 | M41: =L41*Annahmen!$B$73 -> 0 | N41: =H41+K41+M41 -> 220.83679 | O41: =N41/(1+Annahmen!$B$8) -> 185.57713 | P41: =O41*(Annahmen!$B$62*Annahmen!$B$74+(1-Annahmen!$B$62)*Annahmen!$B$75)+(E41*Annahmen!$B$61+E41*(1-Annahmen!$B$61)/12+I41+J41+L41)*(1-Annahmen!$B$62)*Annahmen!$B$76 -> 20.048616 | Q41: =Annahmen!$B$66 -> 4 | R41: =Q41*Annahmen!$B$42 -> 115.48385 | S41: =I41*Annahmen!$B$43+(J41+L41)*Annahmen!$B$44 -> 15.684538 | T41: =C41*Annahmen!$B$77 -> 9.1971099 | U41: =SUMPRODUCT((((Annahmen!$C$145:$C$155="monatlich")*(Annahmen!$D$145:$D$155<=$A41))+((Annahmen!$C$145:$C$155="einmalig")*(Annahmen!$D$145:$D$155=$A41)))*Annahmen!$B$145:$B$155*Annahmen!$E$145:$E$155) -> 69.98508 | V41: =IF($A41>=Annahmen!$B$54,Annahmen!$B$134,0) -> 200 | W41: =MAX(0,(E41-Annahmen!$B$138)/Annahmen!$B$139) -> 0 | X41: =W41*Annahmen!$B$137 -> 0 | Y41: =O41-P41-R41-S41-T41-U41-V41-X41 -> -244.82206 | Z41: =Z40+Y41 -> -7682.2729 | AA41: =IF(Y41>0,1,0) -> 0 | AB41: =IF(Z41>=0,1,0) -> 0
A45: ="Szenario mittel – "&Annahmen!$C$133 -> Szenario mittel – profitabler Nebenerwerb
A46: Monat | B46: Datum | C46: MAU | D46: Neu zahlend | E46: Zahlende gesamt | F46: davon Hörbuch | G46: davon Voll | H46: Abo-Umsatz brutto | I46: Paten Hörbuch | J46: Paten Hörspiel | K46: Paten-Umsatz brutto | L46: Auftrags-Hörspiele | M46: Auftrag brutto | N46: Umsatz brutto | O46: Umsatz netto | P46: Zahlungs-gebühren | Q46: Katalog-Neuwerke | R46: Katalog-kosten | S46: Produktion Paten/Auftrag | T46: Hosting variabel | U46: Fixkosten anteilig | V46: Marketing | W46: Personal-bedarf FTE | X46: Personal-kosten | Y46: Ergebnis | Z46: Ergebnis kumuliert | AA46: BE monatl. | AB46: BE kum.
A47: 1 | B47: 01/2027 | C47: =IF($A47<Annahmen!$C$54,0,Annahmen!$C$55) -> 0 | D47: =C47*Annahmen!$C$58 -> 0 | E47: =D47 -> 0 | F47: =E47*(1-Annahmen!$C$60) -> 0 | G47: =E47*Annahmen!$C$60 -> 0 | H47: =F47*Annahmen!$C$78+G47*Annahmen!$C$79 -> 0 | I47: =IF($A47>=Annahmen!$C$54,Annahmen!$C$63*(1-Annahmen!$C$64),0) -> 0 | J47: =IF($A47>=Annahmen!$C$54,Annahmen!$C$63*Annahmen!$C$64,0) -> 0 | K47: =I47*Annahmen!$B$71+J47*Annahmen!$B$72 -> 0 | L47: =IF($A47>=Annahmen!$C$54,Annahmen!$C$65,0) -> 0 | M47: =L47*Annahmen!$B$73 -> 0 | N47: =H47+K47+M47 -> 0 | O47: =N47/(1+Annahmen!$B$8) -> 0 | P47: =O47*(Annahmen!$C$62*Annahmen!$B$74+(1-Annahmen!$C$62)*Annahmen!$B$75)+(E47*Annahmen!$C$61+E47*(1-Annahmen!$C$61)/12+I47+J47+L47)*(1-Annahmen!$C$62)*Annahmen!$B$76 -> 0 | Q47: =Annahmen!$C$66 -> 8 | R47: =Q47*Annahmen!$B$42 -> 230.9677 | S47: =I47*Annahmen!$B$43+(J47+L47)*Annahmen!$B$44 -> 0 | T47: =C47*Annahmen!$B$77 -> 0 | U47: =SUMPRODUCT((((Annahmen!$C$145:$C$155="monatlich")*(Annahmen!$D$145:$D$155<=$A47))+((Annahmen!$C$145:$C$155="einmalig")*(Annahmen!$D$145:$D$155=$A47)))*Annahmen!$B$145:$B$155*Annahmen!$E$145:$E$155) -> 232.38508 | V47: =IF($A47>=Annahmen!$C$54,Annahmen!$C$134,0) -> 0 | W47: =MAX(0,(E47-Annahmen!$B$138)/Annahmen!$B$139) -> 0 | X47: =W47*Annahmen!$B$137 -> 0 | Y47: =O47-P47-R47-S47-T47-U47-V47-X47 -> -463.35278 | Z47: =Y47 -> -463.35278 | AA47: =IF(Y47>0,1,0) -> 0 | AB47: =IF(Z47>=0,1,0) -> 0
A48: 2 | B48: 02/2027 | C48: =IF($A48<Annahmen!$C$54,0,IF($A48=Annahmen!$C$54,Annahmen!$C$55,C47*(1+Annahmen!$C$56*(1-C47/Annahmen!$C$57)))) -> 0 | D48: =C48*Annahmen!$C$58 -> 0 | E48: =E47*(1-Annahmen!$C$59)+D48 -> 0 | F48: =E48*(1-Annahmen!$C$60) -> 0 | G48: =E48*Annahmen!$C$60 -> 0 | H48: =F48*Annahmen!$C$78+G48*Annahmen!$C$79 -> 0 | I48: =IF($A48>=Annahmen!$C$54,Annahmen!$C$63*(1-Annahmen!$C$64),0) -> 0 | J48: =IF($A48>=Annahmen!$C$54,Annahmen!$C$63*Annahmen!$C$64,0) -> 0 | K48: =I48*Annahmen!$B$71+J48*Annahmen!$B$72 -> 0 | L48: =IF($A48>=Annahmen!$C$54,Annahmen!$C$65,0) -> 0 | M48: =L48*Annahmen!$B$73 -> 0 | N48: =H48+K48+M48 -> 0 | O48: =N48/(1+Annahmen!$B$8) -> 0 | P48: =O48*(Annahmen!$C$62*Annahmen!$B$74+(1-Annahmen!$C$62)*Annahmen!$B$75)+(E48*Annahmen!$C$61+E48*(1-Annahmen!$C$61)/12+I48+J48+L48)*(1-Annahmen!$C$62)*Annahmen!$B$76 -> 0 | Q48: =Annahmen!$C$66 -> 8 | R48: =Q48*Annahmen!$B$42 -> 230.9677 | S48: =I48*Annahmen!$B$43+(J48+L48)*Annahmen!$B$44 -> 0 | T48: =C48*Annahmen!$B$77 -> 0 | U48: =SUMPRODUCT((((Annahmen!$C$145:$C$155="monatlich")*(Annahmen!$D$145:$D$155<=$A48))+((Annahmen!$C$145:$C$155="einmalig")*(Annahmen!$D$145:$D$155=$A48)))*Annahmen!$B$145:$B$155*Annahmen!$E$145:$E$155) -> 92.320468 | V48: =IF($A48>=Annahmen!$C$54,Annahmen!$C$134,0) -> 0 | W48: =MAX(0,(E48-Annahmen!$B$138)/Annahmen!$B$139) -> 0 | X48: =W48*Annahmen!$B$137 -> 0 | Y48: =O48-P48-R48-S48-T48-U48-V48-X48 -> -323.28817 | Z48: =Z47+Y48 -> -786.64095 | AA48: =IF(Y48>0,1,0) -> 0 | AB48: =IF(Z48>=0,1,0) -> 0
A49: 3 | B49: 03/2027 | C49: =IF($A49<Annahmen!$C$54,0,IF($A49=Annahmen!$C$54,Annahmen!$C$55,C48*(1+Annahmen!$C$56*(1-C48/Annahmen!$C$57)))) -> 500 | D49: =C49*Annahmen!$C$58 -> 5 | E49: =E48*(1-Annahmen!$C$59)+D49 -> 5 | F49: =E49*(1-Annahmen!$C$60) -> 3 | G49: =E49*Annahmen!$C$60 -> 2 | H49: =F49*Annahmen!$C$78+G49*Annahmen!$C$79 -> 31.701667 | I49: =IF($A49>=Annahmen!$C$54,Annahmen!$C$63*(1-Annahmen!$C$64),0) -> 1.2 | J49: =IF($A49>=Annahmen!$C$54,Annahmen!$C$63*Annahmen!$C$64,0) -> 0.8 | K49: =I49*Annahmen!$B$71+J49*Annahmen!$B$72 -> 131.98 | L49: =IF($A49>=Annahmen!$C$54,Annahmen!$C$65,0) -> 0.5 | M49: =L49*Annahmen!$B$73 -> 74.5 | N49: =H49+K49+M49 -> 238.18167 | O49: =N49/(1+Annahmen!$B$8) -> 200.15266 | P49: =O49*(Annahmen!$C$62*Annahmen!$B$74+(1-Annahmen!$C$62)*Annahmen!$B$75)+(E49*Annahmen!$C$61+E49*(1-Annahmen!$C$61)/12+I49+J49+L49)*(1-Annahmen!$C$62)*Annahmen!$B$76 -> 17.220928 | Q49: =Annahmen!$C$66 -> 8 | R49: =Q49*Annahmen!$B$42 -> 230.9677 | S49: =I49*Annahmen!$B$43+(J49+L49)*Annahmen!$B$44 -> 79.174498 | T49: =C49*Annahmen!$B$77 -> 5 | U49: =SUMPRODUCT((((Annahmen!$C$145:$C$155="monatlich")*(Annahmen!$D$145:$D$155<=$A49))+((Annahmen!$C$145:$C$155="einmalig")*(Annahmen!$D$145:$D$155=$A49)))*Annahmen!$B$145:$B$155*Annahmen!$E$145:$E$155) -> 69.98508 | V49: =IF($A49>=Annahmen!$C$54,Annahmen!$C$134,0) -> 500 | W49: =MAX(0,(E49-Annahmen!$B$138)/Annahmen!$B$139) -> 0 | X49: =W49*Annahmen!$B$137 -> 0 | Y49: =O49-P49-R49-S49-T49-U49-V49-X49 -> -702.19555 | Z49: =Z48+Y49 -> -1488.8365 | AA49: =IF(Y49>0,1,0) -> 0 | AB49: =IF(Z49>=0,1,0) -> 0
A50: 4 | B50: 04/2027 | C50: =IF($A50<Annahmen!$C$54,0,IF($A50=Annahmen!$C$54,Annahmen!$C$55,C49*(1+Annahmen!$C$56*(1-C49/Annahmen!$C$57)))) -> 574.8125 | D50: =C50*Annahmen!$C$58 -> 5.748125 | E50: =E49*(1-Annahmen!$C$59)+D50 -> 10.448125 | F50: =E50*(1-Annahmen!$C$60) -> 6.268875 | G50: =E50*Annahmen!$C$60 -> 4.17925 | H50: =F50*Annahmen!$C$78+G50*Annahmen!$C$79 -> 66.244595 | I50: =IF($A50>=Annahmen!$C$54,Annahmen!$C$63*(1-Annahmen!$C$64),0) -> 1.2 | J50: =IF($A50>=Annahmen!$C$54,Annahmen!$C$63*Annahmen!$C$64,0) -> 0.8 | K50: =I50*Annahmen!$B$71+J50*Annahmen!$B$72 -> 131.98 | L50: =IF($A50>=Annahmen!$C$54,Annahmen!$C$65,0) -> 0.5 | M50: =L50*Annahmen!$B$73 -> 74.5 | N50: =H50+K50+M50 -> 272.7246 | O50: =N50/(1+Annahmen!$B$8) -> 229.18033 | P50: =O50*(Annahmen!$C$62*Annahmen!$B$74+(1-Annahmen!$C$62)*Annahmen!$B$75)+(E50*Annahmen!$C$61+E50*(1-Annahmen!$C$61)/12+I50+J50+L50)*(1-Annahmen!$C$62)*Annahmen!$B$76 -> 20.047021 | Q50: =Annahmen!$C$66 -> 8 | R50: =Q50*Annahmen!$B$42 -> 230.9677 | S50: =I50*Annahmen!$B$43+(J50+L50)*Annahmen!$B$44 -> 79.174498 | T50: =C50*Annahmen!$B$77 -> 5.748125 | U50: =SUMPRODUCT((((Annahmen!$C$145:$C$155="monatlich")*(Annahmen!$D$145:$D$155<=$A50))+((Annahmen!$C$145:$C$155="einmalig")*(Annahmen!$D$145:$D$155=$A50)))*Annahmen!$B$145:$B$155*Annahmen!$E$145:$E$155) -> 69.98508 | V50: =IF($A50>=Annahmen!$C$54,Annahmen!$C$134,0) -> 500 | W50: =MAX(0,(E50-Annahmen!$B$138)/Annahmen!$B$139) -> 0 | X50: =W50*Annahmen!$B$137 -> 0 | Y50: =O50-P50-R50-S50-T50-U50-V50-X50 -> -676.74209 | Z50: =Z49+Y50 -> -2165.5786 | AA50: =IF(Y50>0,1,0) -> 0 | AB50: =IF(Z50>=0,1,0) -> 0
A51: 5 | B51: 05/2027 | C51: =IF($A51<Annahmen!$C$54,0,IF($A51=Annahmen!$C$54,Annahmen!$C$55,C50*(1+Annahmen!$C$56*(1-C50/Annahmen!$C$57)))) -> 660.78657 | D51: =C51*Annahmen!$C$58 -> 6.6078657 | E51: =E50*(1-Annahmen!$C$59)+D51 -> 16.429103 | F51: =E51*(1-Annahmen!$C$60) -> 9.8574619 | G51: =E51*Annahmen!$C$60 -> 6.5716413 | H51: =F51*Annahmen!$C$78+G51*Annahmen!$C$79 -> 104.16599 | I51: =IF($A51>=Annahmen!$C$54,Annahmen!$C$63*(1-Annahmen!$C$64),0) -> 1.2 | J51: =IF($A51>=Annahmen!$C$54,Annahmen!$C$63*Annahmen!$C$64,0) -> 0.8 | K51: =I51*Annahmen!$B$71+J51*Annahmen!$B$72 -> 131.98 | L51: =IF($A51>=Annahmen!$C$54,Annahmen!$C$65,0) -> 0.5 | M51: =L51*Annahmen!$B$73 -> 74.5 | N51: =H51+K51+M51 -> 310.64599 | O51: =N51/(1+Annahmen!$B$8) -> 261.04705 | P51: =O51*(Annahmen!$C$62*Annahmen!$B$74+(1-Annahmen!$C$62)*Annahmen!$B$75)+(E51*Annahmen!$C$61+E51*(1-Annahmen!$C$61)/12+I51+J51+L51)*(1-Annahmen!$C$62)*Annahmen!$B$76 -> 23.149519 | Q51: =Annahmen!$C$66 -> 8 | R51: =Q51*Annahmen!$B$42 -> 230.9677 | S51: =I51*Annahmen!$B$43+(J51+L51)*Annahmen!$B$44 -> 79.174498 | T51: =C51*Annahmen!$B$77 -> 6.6078657 | U51: =SUMPRODUCT((((Annahmen!$C$145:$C$155="monatlich")*(Annahmen!$D$145:$D$155<=$A51))+((Annahmen!$C$145:$C$155="einmalig")*(Annahmen!$D$145:$D$155=$A51)))*Annahmen!$B$145:$B$155*Annahmen!$E$145:$E$155) -> 309.98508 | V51: =IF($A51>=Annahmen!$C$54,Annahmen!$C$134,0) -> 500 | W51: =MAX(0,(E51-Annahmen!$B$138)/Annahmen!$B$139) -> 0 | X51: =W51*Annahmen!$B$137 -> 0 | Y51: =O51-P51-R51-S51-T51-U51-V51-X51 -> -888.83761 | Z51: =Z50+Y51 -> -3054.4162 | AA51: =IF(Y51>0,1,0) -> 0 | AB51: =IF(Z51>=0,1,0) -> 0
A52: 6 | B52: 06/2027 | C52: =IF($A52<Annahmen!$C$54,0,IF($A52=Annahmen!$C$54,Annahmen!$C$55,C51*(1+Annahmen!$C$56*(1-C51/Annahmen!$C$57)))) -> 759.57707 | D52: =C52*Annahmen!$C$58 -> 7.5957707 | E52: =E51*(1-Annahmen!$C$59)+D52 -> 23.039128 | F52: =E52*(1-Annahmen!$C$60) -> 13.823477 | G52: =E52*Annahmen!$C$60 -> 9.2156511 | H52: =F52*Annahmen!$C$78+G52*Annahmen!$C$79 -> 146.07575 | I52: =IF($A52>=Annahmen!$C$54,Annahmen!$C$63*(1-Annahmen!$C$64),0) -> 1.2 | J52: =IF($A52>=Annahmen!$C$54,Annahmen!$C$63*Annahmen!$C$64,0) -> 0.8 | K52: =I52*Annahmen!$B$71+J52*Annahmen!$B$72 -> 131.98 | L52: =IF($A52>=Annahmen!$C$54,Annahmen!$C$65,0) -> 0.5 | M52: =L52*Annahmen!$B$73 -> 74.5 | N52: =H52+K52+M52 -> 352.55575 | O52: =N52/(1+Annahmen!$B$8) -> 296.26534 | P52: =O52*(Annahmen!$C$62*Annahmen!$B$74+(1-Annahmen!$C$62)*Annahmen!$B$75)+(E52*Annahmen!$C$61+E52*(1-Annahmen!$C$61)/12+I52+J52+L52)*(1-Annahmen!$C$62)*Annahmen!$B$76 -> 26.578321 | Q52: =Annahmen!$C$66 -> 8 | R52: =Q52*Annahmen!$B$42 -> 230.9677 | S52: =I52*Annahmen!$B$43+(J52+L52)*Annahmen!$B$44 -> 79.174498 | T52: =C52*Annahmen!$B$77 -> 7.5957707 | U52: =SUMPRODUCT((((Annahmen!$C$145:$C$155="monatlich")*(Annahmen!$D$145:$D$155<=$A52))+((Annahmen!$C$145:$C$155="einmalig")*(Annahmen!$D$145:$D$155=$A52)))*Annahmen!$B$145:$B$155*Annahmen!$E$145:$E$155) -> 69.98508 | V52: =IF($A52>=Annahmen!$C$54,Annahmen!$C$134,0) -> 500 | W52: =MAX(0,(E52-Annahmen!$B$138)/Annahmen!$B$139) -> 0 | X52: =W52*Annahmen!$B$137 -> 0 | Y52: =O52-P52-R52-S52-T52-U52-V52-X52 -> -618.03604 | Z52: =Z51+Y52 -> -3672.4522 | AA52: =IF(Y52>0,1,0) -> 0 | AB52: =IF(Z52>=0,1,0) -> 0
A53: 7 | B53: 07/2027 | C53: =IF($A53<Annahmen!$C$54,0,IF($A53=Annahmen!$C$54,Annahmen!$C$55,C52*(1+Annahmen!$C$56*(1-C52/Annahmen!$C$57)))) -> 873.08092 | D53: =C53*Annahmen!$C$58 -> 8.7308092 | E53: =E52*(1-Annahmen!$C$59)+D53 -> 30.387589 | F53: =E53*(1-Annahmen!$C$60) -> 18.232554 | G53: =E53*Annahmen!$C$60 -> 12.155036 | H53: =F53*Annahmen!$C$78+G53*Annahmen!$C$79 -> 192.66744 | I53: =IF($A53>=Annahmen!$C$54,Annahmen!$C$63*(1-Annahmen!$C$64),0) -> 1.2 | J53: =IF($A53>=Annahmen!$C$54,Annahmen!$C$63*Annahmen!$C$64,0) -> 0.8 | K53: =I53*Annahmen!$B$71+J53*Annahmen!$B$72 -> 131.98 | L53: =IF($A53>=Annahmen!$C$54,Annahmen!$C$65,0) -> 0.5 | M53: =L53*Annahmen!$B$73 -> 74.5 | N53: =H53+K53+M53 -> 399.14744 | O53: =N53/(1+Annahmen!$B$8) -> 335.41802 | P53: =O53*(Annahmen!$C$62*Annahmen!$B$74+(1-Annahmen!$C$62)*Annahmen!$B$75)+(E53*Annahmen!$C$61+E53*(1-Annahmen!$C$61)/12+I53+J53+L53)*(1-Annahmen!$C$62)*Annahmen!$B$76 -> 30.390171 | Q53: =Annahmen!$C$66 -> 8 | R53: =Q53*Annahmen!$B$42 -> 230.9677 | S53: =I53*Annahmen!$B$43+(J53+L53)*Annahmen!$B$44 -> 79.174498 | T53: =C53*Annahmen!$B$77 -> 8.7308092 | U53: =SUMPRODUCT((((Annahmen!$C$145:$C$155="monatlich")*(Annahmen!$D$145:$D$155<=$A53))+((Annahmen!$C$145:$C$155="einmalig")*(Annahmen!$D$145:$D$155=$A53)))*Annahmen!$B$145:$B$155*Annahmen!$E$145:$E$155) -> 69.98508 | V53: =IF($A53>=Annahmen!$C$54,Annahmen!$C$134,0) -> 500 | W53: =MAX(0,(E53-Annahmen!$B$138)/Annahmen!$B$139) -> 0 | X53: =W53*Annahmen!$B$137 -> 0 | Y53: =O53-P53-R53-S53-T53-U53-V53-X53 -> -583.83024 | Z53: =Z52+Y53 -> -4256.2825 | AA53: =IF(Y53>0,1,0) -> 0 | AB53: =IF(Z53>=0,1,0) -> 0
A54: 8 | B54: 08/2027 | C54: =IF($A54<Annahmen!$C$54,0,IF($A54=Annahmen!$C$54,Annahmen!$C$55,C53*(1+Annahmen!$C$56*(1-C53/Annahmen!$C$57)))) -> 1003.4714 | D54: =C54*Annahmen!$C$58 -> 10.034714 | E54: =E53*(1-Annahmen!$C$59)+D54 -> 38.599047 | F54: =E54*(1-Annahmen!$C$60) -> 23.159428 | G54: =E54*Annahmen!$C$60 -> 15.439619 | H54: =F54*Annahmen!$C$78+G54*Annahmen!$C$79 -> 244.73083 | I54: =IF($A54>=Annahmen!$C$54,Annahmen!$C$63*(1-Annahmen!$C$64),0) -> 1.2 | J54: =IF($A54>=Annahmen!$C$54,Annahmen!$C$63*Annahmen!$C$64,0) -> 0.8 | K54: =I54*Annahmen!$B$71+J54*Annahmen!$B$72 -> 131.98 | L54: =IF($A54>=Annahmen!$C$54,Annahmen!$C$65,0) -> 0.5 | M54: =L54*Annahmen!$B$73 -> 74.5 | N54: =H54+K54+M54 -> 451.21083 | O54: =N54/(1+Annahmen!$B$8) -> 379.16876 | P54: =O54*(Annahmen!$C$62*Annahmen!$B$74+(1-Annahmen!$C$62)*Annahmen!$B$75)+(E54*Annahmen!$C$61+E54*(1-Annahmen!$C$61)/12+I54+J54+L54)*(1-Annahmen!$C$62)*Annahmen!$B$76 -> 34.649681 | Q54: =Annahmen!$C$66 -> 8 | R54: =Q54*Annahmen!$B$42 -> 230.9677 | S54: =I54*Annahmen!$B$43+(J54+L54)*Annahmen!$B$44 -> 79.174498 | T54: =C54*Annahmen!$B$77 -> 10.034714 | U54: =SUMPRODUCT((((Annahmen!$C$145:$C$155="monatlich")*(Annahmen!$D$145:$D$155<=$A54))+((Annahmen!$C$145:$C$155="einmalig")*(Annahmen!$D$145:$D$155=$A54)))*Annahmen!$B$145:$B$155*Annahmen!$E$145:$E$155) -> 69.98508 | V54: =IF($A54>=Annahmen!$C$54,Annahmen!$C$134,0) -> 500 | W54: =MAX(0,(E54-Annahmen!$B$138)/Annahmen!$B$139) -> 0 | X54: =W54*Annahmen!$B$137 -> 0 | Y54: =O54-P54-R54-S54-T54-U54-V54-X54 -> -545.64291 | Z54: =Z53+Y54 -> -4801.9254 | AA54: =IF(Y54>0,1,0) -> 0 | AB54: =IF(Z54>=0,1,0) -> 0
A55: 9 | B55: 09/2027 | C55: =IF($A55<Annahmen!$C$54,0,IF($A55=Annahmen!$C$54,Annahmen!$C$55,C54*(1+Annahmen!$C$56*(1-C54/Annahmen!$C$57)))) -> 1153.2368 | D55: =C55*Annahmen!$C$58 -> 11.532368 | E55: =E54*(1-Annahmen!$C$59)+D55 -> 47.815473 | F55: =E55*(1-Annahmen!$C$60) -> 28.689284 | G55: =E55*Annahmen!$C$60 -> 19.126189 | H55: =F55*Annahmen!$C$78+G55*Annahmen!$C$79 -> 303.16604 | I55: =IF($A55>=Annahmen!$C$54,Annahmen!$C$63*(1-Annahmen!$C$64),0) -> 1.2 | J55: =IF($A55>=Annahmen!$C$54,Annahmen!$C$63*Annahmen!$C$64,0) -> 0.8 | K55: =I55*Annahmen!$B$71+J55*Annahmen!$B$72 -> 131.98 | L55: =IF($A55>=Annahmen!$C$54,Annahmen!$C$65,0) -> 0.5 | M55: =L55*Annahmen!$B$73 -> 74.5 | N55: =H55+K55+M55 -> 509.64604 | O55: =N55/(1+Annahmen!$B$8) -> 428.27398 | P55: =O55*(Annahmen!$C$62*Annahmen!$B$74+(1-Annahmen!$C$62)*Annahmen!$B$75)+(E55*Annahmen!$C$61+E55*(1-Annahmen!$C$61)/12+I55+J55+L55)*(1-Annahmen!$C$62)*Annahmen!$B$76 -> 39.430495 | Q55: =Annahmen!$C$66 -> 8 | R55: =Q55*Annahmen!$B$42 -> 230.9677 | S55: =I55*Annahmen!$B$43+(J55+L55)*Annahmen!$B$44 -> 79.174498 | T55: =C55*Annahmen!$B$77 -> 11.532368 | U55: =SUMPRODUCT((((Annahmen!$C$145:$C$155="monatlich")*(Annahmen!$D$145:$D$155<=$A55))+((Annahmen!$C$145:$C$155="einmalig")*(Annahmen!$D$145:$D$155=$A55)))*Annahmen!$B$145:$B$155*Annahmen!$E$145:$E$155) -> 69.98508 | V55: =IF($A55>=Annahmen!$C$54,Annahmen!$C$134,0) -> 500 | W55: =MAX(0,(E55-Annahmen!$B$138)/Annahmen!$B$139) -> 0 | X55: =W55*Annahmen!$B$137 -> 0 | Y55: =O55-P55-R55-S55-T55-U55-V55-X55 -> -502.81616 | Z55: =Z54+Y55 -> -5304.7416 | AA55: =IF(Y55>0,1,0) -> 0 | AB55: =IF(Z55>=0,1,0) -> 0
A56: 10 | B56: 10/2027 | C56: =IF($A56<Annahmen!$C$54,0,IF($A56=Annahmen!$C$54,Annahmen!$C$55,C55*(1+Annahmen!$C$56*(1-C55/Annahmen!$C$57)))) -> 1325.2249 | D56: =C56*Annahmen!$C$58 -> 13.252249 | E56: =E55*(1-Annahmen!$C$59)+D56 -> 58.198794 | F56: =E56*(1-Annahmen!$C$60) -> 34.919276 | G56: =E56*Annahmen!$C$60 -> 23.279517 | H56: =F56*Annahmen!$C$78+G56*Annahmen!$C$79 -> 368.99975 | I56: =IF($A56>=Annahmen!$C$54,Annahmen!$C$63*(1-Annahmen!$C$64),0) -> 1.2 | J56: =IF($A56>=Annahmen!$C$54,Annahmen!$C$63*Annahmen!$C$64,0) -> 0.8 | K56: =I56*Annahmen!$B$71+J56*Annahmen!$B$72 -> 131.98 | L56: =IF($A56>=Annahmen!$C$54,Annahmen!$C$65,0) -> 0.5 | M56: =L56*Annahmen!$B$73 -> 74.5 | N56: =H56+K56+M56 -> 575.47975 | O56: =N56/(1+Annahmen!$B$8) -> 483.59643 | P56: =O56*(Annahmen!$C$62*Annahmen!$B$74+(1-Annahmen!$C$62)*Annahmen!$B$75)+(E56*Annahmen!$C$61+E56*(1-Annahmen!$C$61)/12+I56+J56+L56)*(1-Annahmen!$C$62)*Annahmen!$B$76 -> 44.81661 | Q56: =Annahmen!$C$66 -> 8 | R56: =Q56*Annahmen!$B$42 -> 230.9677 | S56: =I56*Annahmen!$B$43+(J56+L56)*Annahmen!$B$44 -> 79.174498 | T56: =C56*Annahmen!$B$77 -> 13.252249 | U56: =SUMPRODUCT((((Annahmen!$C$145:$C$155="monatlich")*(Annahmen!$D$145:$D$155<=$A56))+((Annahmen!$C$145:$C$155="einmalig")*(Annahmen!$D$145:$D$155=$A56)))*Annahmen!$B$145:$B$155*Annahmen!$E$145:$E$155) -> 69.98508 | V56: =IF($A56>=Annahmen!$C$54,Annahmen!$C$134,0) -> 500 | W56: =MAX(0,(E56-Annahmen!$B$138)/Annahmen!$B$139) -> 0 | X56: =W56*Annahmen!$B$137 -> 0 | Y56: =O56-P56-R56-S56-T56-U56-V56-X56 -> -454.59971 | Z56: =Z55+Y56 -> -5759.3413 | AA56: =IF(Y56>0,1,0) -> 0 | AB56: =IF(Z56>=0,1,0) -> 0
...

Sheet Read Layer
A1: Read Layer Verlagsdienstleistungen (B2B) — 24 Monate ab 01/2027
A3: Kennzahl | B3: ="vorsichtig – "&Annahmen!$B$133 -> vorsichtig – teures Hobby | C3: ="mittel – "&Annahmen!$C$133 -> mittel – profitabler Nebenerwerb | D3: ="stark – "&Annahmen!$D$133 -> stark – skalierbares Business
A4: Break-even monatlich (erster Monat Ergebnis > 0) | B4: =IFERROR("Monat "&MATCH(1,AC18:AC41,0)&" ("&INDEX($B$18:$B$41,MATCH(1,AC18:AC41,0))&")","nicht in 24 M") -> Monat 8 (08/2027) | C4: =IFERROR("Monat "&MATCH(1,AC47:AC70,0)&" ("&INDEX($B$47:$B$70,MATCH(1,AC47:AC70,0))&")","nicht in 24 M") -> Monat 4 (04/2027) | D4: =IFERROR("Monat "&MATCH(1,AC76:AC99,0)&" ("&INDEX($B$76:$B$99,MATCH(1,AC76:AC99,0))&")","nicht in 24 M") -> Monat 3 (03/2027)
A5: Break-even kumuliert (erster Monat kum. ≥ 0) | B5: =IFERROR("Monat "&MATCH(1,AD18:AD41,0)&" ("&INDEX($B$18:$B$41,MATCH(1,AD18:AD41,0))&")","nicht in 24 M") -> Monat 14 (02/2028) | C5: =IFERROR("Monat "&MATCH(1,AD47:AD70,0)&" ("&INDEX($B$47:$B$70,MATCH(1,AD47:AD70,0))&")","nicht in 24 M") -> Monat 4 (04/2027) | D5: =IFERROR("Monat "&MATCH(1,AD76:AD99,0)&" ("&INDEX($B$76:$B$99,MATCH(1,AD76:AD99,0))&")","nicht in 24 M") -> Monat 3 (03/2027)
A6: Deckungsbeitrag je Auftrag (Preis – Rechenkosten)
A7: Pilot (bezahlt) | B7: =Annahmen!$B$96-Annahmen!$B$51 -> 473.80631
A8: BFSG-EPUB ohne Audio | B8: =Annahmen!$B$97-Annahmen!$B$45 -> 148.72243
A9: BFSG-EPUB + Media Overlays | B9: =Annahmen!$B$97+Annahmen!$B$98-Annahmen!$B$47 -> 530.32826
A10: Alignment Verlagsaudio (ohne / mit Schnitt) | B10: =Annahmen!$B$99-Annahmen!$B$48 -> 188.55243 | C10: =Annahmen!$B$99+Annahmen!$B$102-Annahmen!$B$48 -> 317.58469
A11: Schnitt-Aufschlag je Titel (Vorschlag) | B11: =Annahmen!$B$102 -> 129.03226
A12: Vertonung je Audio-h | B12: =Annahmen!$B$103-Annahmen!$B$49 -> 87.416654
A13: Übersetzung je Normseite | B13: =Annahmen!$B$104-Annahmen!$B$50 -> 5.9798982
A14: Barter-Piloten erzeugen Kosten ohne Umsatz. B2B-Zahlung per Rechnung/SEPA – keine Zahlungsgebühren angesetzt. Preise netto zzgl. MwSt.
A16: ="Szenario vorsichtig – "&Annahmen!$B$133 -> Szenario vorsichtig – teures Hobby
A17: Monat | B17: Datum | C17: Piloten | D17: davon Barter | E17: Pilot-Umsatz | F17: Folge-aufträge | G17: Folge-Umsatz (nach Anrechnung) | H17: BFSG-EPUB Titel | I17: Umsatz BFSG/MO | J17: Alignment Titel | K17: Umsatz Alignment | L17: Vertonung Audio-h | M17: Umsatz Vertonung | N17: Übersetzung NS | O17: Umsatz Übersetzung | P17: Modernisierung NS | Q17: Umsatz Moderni-sierung | R17: Zusatz-formate | S17: Umsatz Formate | T17: Umsatz gesamt | U17: Rechen-kosten | V17: Fixkosten anteilig | W17: Marketing | X17: Titel-Äquiv. | Y17: Personal-bedarf FTE | Z17: Personal-kosten | AA17: Ergebnis | AB17: Ergebnis kumuliert | AC17: BE monatl. | AD17: BE kum.
A18: 1 | B18: 01/2027 | C18: =IF($A18>=Annahmen!$B$82,Annahmen!$B$83,0) -> 0 | D18: =C18*Annahmen!$B$84 -> 0 | E18: =(C18-D18)*Annahmen!$B$96 -> 0 | F18: =IF($A18>Annahmen!$B$86,INDEX($C$18:$C$41,$A18-Annahmen!$B$86)*Annahmen!$B$85,0) -> 0 | G18: =F18*(Annahmen!$B$87*(Annahmen!$B$97+Annahmen!$B$98)-Annahmen!$B$96*(1-Annahmen!$B$84)) -> 0 | H18: =IF($A18>=Annahmen!$B$82,Annahmen!$B$88,0) -> 0 | I18: =H18*(Annahmen!$B$97+Annahmen!$B$89*Annahmen!$B$98) -> 0 | J18: =IF($A18>=Annahmen!$B$82,Annahmen!$B$90,0) -> 0 | K18: =J18*(Annahmen!$B$99+Annahmen!$B$91*Annahmen!$B$102) -> 0 | L18: =IF($A18>=Annahmen!$B$82,Annahmen!$B$92,0) -> 0 | M18: =L18*Annahmen!$B$103 -> 0 | N18: =IF($A18>=Annahmen!$B$82,Annahmen!$B$93,0) -> 0 | O18: =N18*Annahmen!$B$104 -> 0 | P18: =IF($A18>=Annahmen!$B$82,Annahmen!$B$94,0) -> 0 | Q18: =P18*Annahmen!$B$105 -> 0 | R18: =IF($A18>=Annahmen!$B$82,Annahmen!$B$95,0) -> 0 | S18: =R18*Annahmen!$B$106 -> 0 | T18: =E18+G18+I18+K18+M18+O18+Q18+S18 -> 0 | U18: =C18*Annahmen!$B$51+F18*Annahmen!$B$87*Annahmen!$B$47+H18*(Annahmen!$B$45+Annahmen!$B$89*(Annahmen!$B$47-Annahmen!$B$45))+J18*Annahmen!$B$48+L18*Annahmen!$B$49+(N18+P18)*Annahmen!$B$50 -> 0 | V18: =SUMPRODUCT((((Annahmen!$C$145:$C$155="monatlich")*(Annahmen!$D$145:$D$155<=$A18))+((Annahmen!$C$145:$C$155="einmalig")*(Annahmen!$D$145:$D$155=$A18)))*Annahmen!$B$145:$B$155*Annahmen!$F$145:$F$155) -> 213.22757 | W18: =Annahmen!$B$135 -> 50 | X18: =C18+F18*Annahmen!$B$87+H18+J18+L18/Annahmen!$B$46+(N18+P18)/(Annahmen!$B$23/Annahmen!$B$24) -> 0 | Y18: =MAX(0,(X18-Annahmen!$B$140)/Annahmen!$B$141) -> 0 | Z18: =Y18*Annahmen!$B$137 -> 0 | AA18: =T18-U18-V18-W18-Z18 -> -263.22757 | AB18: =AA18 -> -263.22757 | AC18: =IF(AA18>0,1,0) -> 0 | AD18: =IF(AB18>=0,1,0) -> 0
A19: 2 | B19: 02/2027 | C19: =IF($A19>=Annahmen!$B$82,Annahmen!$B$83,0) -> 0 | D19: =C19*Annahmen!$B$84 -> 0 | E19: =(C19-D19)*Annahmen!$B$96 -> 0 | F19: =IF($A19>Annahmen!$B$86,INDEX($C$18:$C$41,$A19-Annahmen!$B$86)*Annahmen!$B$85,0) -> 0 | G19: =F19*(Annahmen!$B$87*(Annahmen!$B$97+Annahmen!$B$98)-Annahmen!$B$96*(1-Annahmen!$B$84)) -> 0 | H19: =IF($A19>=Annahmen!$B$82,Annahmen!$B$88,0) -> 0 | I19: =H19*(Annahmen!$B$97+Annahmen!$B$89*Annahmen!$B$98) -> 0 | J19: =IF($A19>=Annahmen!$B$82,Annahmen!$B$90,0) -> 0 | K19: =J19*(Annahmen!$B$99+Annahmen!$B$91*Annahmen!$B$102) -> 0 | L19: =IF($A19>=Annahmen!$B$82,Annahmen!$B$92,0) -> 0 | M19: =L19*Annahmen!$B$103 -> 0 | N19: =IF($A19>=Annahmen!$B$82,Annahmen!$B$93,0) -> 0 | O19: =N19*Annahmen!$B$104 -> 0 | P19: =IF($A19>=Annahmen!$B$82,Annahmen!$B$94,0) -> 0 | Q19: =P19*Annahmen!$B$105 -> 0 | R19: =IF($A19>=Annahmen!$B$82,Annahmen!$B$95,0) -> 0 | S19: =R19*Annahmen!$B$106 -> 0 | T19: =E19+G19+I19+K19+M19+O19+Q19+S19 -> 0 | U19: =C19*Annahmen!$B$51+F19*Annahmen!$B$87*Annahmen!$B$47+H19*(Annahmen!$B$45+Annahmen!$B$89*(Annahmen!$B$47-Annahmen!$B$45))+J19*Annahmen!$B$48+L19*Annahmen!$B$49+(N19+P19)*Annahmen!$B$50 -> 0 | V19: =SUMPRODUCT((((Annahmen!$C$145:$C$155="monatlich")*(Annahmen!$D$145:$D$155<=$A19))+((Annahmen!$C$145:$C$155="einmalig")*(Annahmen!$D$145:$D$155=$A19)))*Annahmen!$B$145:$B$155*Annahmen!$F$145:$F$155) -> 50.827571 | W19: =Annahmen!$B$135 -> 50 | X19: =C19+F19*Annahmen!$B$87+H19+J19+L19/Annahmen!$B$46+(N19+P19)/(Annahmen!$B$23/Annahmen!$B$24) -> 0 | Y19: =MAX(0,(X19-Annahmen!$B$140)/Annahmen!$B$141) -> 0 | Z19: =Y19*Annahmen!$B$137 -> 0 | AA19: =T19-U19-V19-W19-Z19 -> -100.82757 | AB19: =AB18+AA19 -> -364.05514 | AC19: =IF(AA19>0,1,0) -> 0 | AD19: =IF(AB19>=0,1,0) -> 0
A20: 3 | B20: 03/2027 | C20: =IF($A20>=Annahmen!$B$82,Annahmen!$B$83,0) -> 0 | D20: =C20*Annahmen!$B$84 -> 0 | E20: =(C20-D20)*Annahmen!$B$96 -> 0 | F20: =IF($A20>Annahmen!$B$86,INDEX($C$18:$C$41,$A20-Annahmen!$B$86)*Annahmen!$B$85,0) -> 0 | G20: =F20*(Annahmen!$B$87*(Annahmen!$B$97+Annahmen!$B$98)-Annahmen!$B$96*(1-Annahmen!$B$84)) -> 0 | H20: =IF($A20>=Annahmen!$B$82,Annahmen!$B$88,0) -> 0 | I20: =H20*(Annahmen!$B$97+Annahmen!$B$89*Annahmen!$B$98) -> 0 | J20: =IF($A20>=Annahmen!$B$82,Annahmen!$B$90,0) -> 0 | K20: =J20*(Annahmen!$B$99+Annahmen!$B$91*Annahmen!$B$102) -> 0 | L20: =IF($A20>=Annahmen!$B$82,Annahmen!$B$92,0) -> 0 | M20: =L20*Annahmen!$B$103 -> 0 | N20: =IF($A20>=Annahmen!$B$82,Annahmen!$B$93,0) -> 0 | O20: =N20*Annahmen!$B$104 -> 0 | P20: =IF($A20>=Annahmen!$B$82,Annahmen!$B$94,0) -> 0 | Q20: =P20*Annahmen!$B$105 -> 0 | R20: =IF($A20>=Annahmen!$B$82,Annahmen!$B$95,0) -> 0 | S20: =R20*Annahmen!$B$106 -> 0 | T20: =E20+G20+I20+K20+M20+O20+Q20+S20 -> 0 | U20: =C20*Annahmen!$B$51+F20*Annahmen!$B$87*Annahmen!$B$47+H20*(Annahmen!$B$45+Annahmen!$B$89*(Annahmen!$B$47-Annahmen!$B$45))+J20*Annahmen!$B$48+L20*Annahmen!$B$49+(N20+P20)*Annahmen!$B$50 -> 0 | V20: =SUMPRODUCT((((Annahmen!$C$145:$C$155="monatlich")*(Annahmen!$D$145:$D$155<=$A20))+((Annahmen!$C$145:$C$155="einmalig")*(Annahmen!$D$145:$D$155=$A20)))*Annahmen!$B$145:$B$155*Annahmen!$F$145:$F$155) -> 330.82757 | W20: =Annahmen!$B$135 -> 50 | X20: =C20+F20*Annahmen!$B$87+H20+J20+L20/Annahmen!$B$46+(N20+P20)/(Annahmen!$B$23/Annahmen!$B$24) -> 0 | Y20: =MAX(0,(X20-Annahmen!$B$140)/Annahmen!$B$141) -> 0 | Z20: =Y20*Annahmen!$B$137 -> 0 | AA20: =T20-U20-V20-W20-Z20 -> -380.82757 | AB20: =AB19+AA20 -> -744.88271 | AC20: =IF(AA20>0,1,0) -> 0 | AD20: =IF(AB20>=0,1,0) -> 0
A21: 4 | B21: 04/2027 | C21: =IF($A21>=Annahmen!$B$82,Annahmen!$B$83,0) -> 0 | D21: =C21*Annahmen!$B$84 -> 0 | E21: =(C21-D21)*Annahmen!$B$96 -> 0 | F21: =IF($A21>Annahmen!$B$86,INDEX($C$18:$C$41,$A21-Annahmen!$B$86)*Annahmen!$B$85,0) -> 0 | G21: =F21*(Annahmen!$B$87*(Annahmen!$B$97+Annahmen!$B$98)-Annahmen!$B$96*(1-Annahmen!$B$84)) -> 0 | H21: =IF($A21>=Annahmen!$B$82,Annahmen!$B$88,0) -> 0 | I21: =H21*(Annahmen!$B$97+Annahmen!$B$89*Annahmen!$B$98) -> 0 | J21: =IF($A21>=Annahmen!$B$82,Annahmen!$B$90,0) -> 0 | K21: =J21*(Annahmen!$B$99+Annahmen!$B$91*Annahmen!$B$102) -> 0 | L21: =IF($A21>=Annahmen!$B$82,Annahmen!$B$92,0) -> 0 | M21: =L21*Annahmen!$B$103 -> 0 | N21: =IF($A21>=Annahmen!$B$82,Annahmen!$B$93,0) -> 0 | O21: =N21*Annahmen!$B$104 -> 0 | P21: =IF($A21>=Annahmen!$B$82,Annahmen!$B$94,0) -> 0 | Q21: =P21*Annahmen!$B$105 -> 0 | R21: =IF($A21>=Annahmen!$B$82,Annahmen!$B$95,0) -> 0 | S21: =R21*Annahmen!$B$106 -> 0 | T21: =E21+G21+I21+K21+M21+O21+Q21+S21 -> 0 | U21: =C21*Annahmen!$B$51+F21*Annahmen!$B$87*Annahmen!$B$47+H21*(Annahmen!$B$45+Annahmen!$B$89*(Annahmen!$B$47-Annahmen!$B$45))+J21*Annahmen!$B$48+L21*Annahmen!$B$49+(N21+P21)*Annahmen!$B$50 -> 0 | V21: =SUMPRODUCT((((Annahmen!$C$145:$C$155="monatlich")*(Annahmen!$D$145:$D$155<=$A21))+((Annahmen!$C$145:$C$155="einmalig")*(Annahmen!$D$145:$D$155=$A21)))*Annahmen!$B$145:$B$155*Annahmen!$F$145:$F$155) -> 50.827571 | W21: =Annahmen!$B$135 -> 50 | X21: =C21+F21*Annahmen!$B$87+H21+J21+L21/Annahmen!$B$46+(N21+P21)/(Annahmen!$B$23/Annahmen!$B$24) -> 0 | Y21: =MAX(0,(X21-Annahmen!$B$140)/Annahmen!$B$141) -> 0 | Z21: =Y21*Annahmen!$B$137 -> 0 | AA21: =T21-U21-V21-W21-Z21 -> -100.82757 | AB21: =AB20+AA21 -> -845.71028 | AC21: =IF(AA21>0,1,0) -> 0 | AD21: =IF(AB21>=0,1,0) -> 0
A22: 5 | B22: 05/2027 | C22: =IF($A22>=Annahmen!$B$82,Annahmen!$B$83,0) -> 0.3 | D22: =C22*Annahmen!$B$84 -> 0.09 | E22: =(C22-D22)*Annahmen!$B$96 -> 102.9 | F22: =IF($A22>Annahmen!$B$86,INDEX($C$18:$C$41,$A22-Annahmen!$B$86)*Annahmen!$B$85,0) -> 0 | G22: =F22*(Annahmen!$B$87*(Annahmen!$B$97+Annahmen!$B$98)-Annahmen!$B$96*(1-Annahmen!$B$84)) -> 0 | H22: =IF($A22>=Annahmen!$B$82,Annahmen!$B$88,0) -> 0 | I22: =H22*(Annahmen!$B$97+Annahmen!$B$89*Annahmen!$B$98) -> 0 | J22: =IF($A22>=Annahmen!$B$82,Annahmen!$B$90,0) -> 0 | K22: =J22*(Annahmen!$B$99+Annahmen!$B$91*Annahmen!$B$102) -> 0 | L22: =IF($A22>=Annahmen!$B$82,Annahmen!$B$92,0) -> 0 | M22: =L22*Annahmen!$B$103 -> 0 | N22: =IF($A22>=Annahmen!$B$82,Annahmen!$B$93,0) -> 0 | O22: =N22*Annahmen!$B$104 -> 0 | P22: =IF($A22>=Annahmen!$B$82,Annahmen!$B$94,0) -> 0 | Q22: =P22*Annahmen!$B$105 -> 0 | R22: =IF($A22>=Annahmen!$B$82,Annahmen!$B$95,0) -> 0 | S22: =R22*Annahmen!$B$106 -> 0 | T22: =E22+G22+I22+K22+M22+O22+Q22+S22 -> 102.9 | U22: =C22*Annahmen!$B$51+F22*Annahmen!$B$87*Annahmen!$B$47+H22*(Annahmen!$B$45+Annahmen!$B$89*(Annahmen!$B$47-Annahmen!$B$45))+J22*Annahmen!$B$48+L22*Annahmen!$B$49+(N22+P22)*Annahmen!$B$50 -> 4.8581085 | V22: =SUMPRODUCT((((Annahmen!$C$145:$C$155="monatlich")*(Annahmen!$D$145:$D$155<=$A22))+((Annahmen!$C$145:$C$155="einmalig")*(Annahmen!$D$145:$D$155=$A22)))*Annahmen!$B$145:$B$155*Annahmen!$F$145:$F$155) -> 610.82757 | W22: =Annahmen!$B$135 -> 50 | X22: =C22+F22*Annahmen!$B$87+H22+J22+L22/Annahmen!$B$46+(N22+P22)/(Annahmen!$B$23/Annahmen!$B$24) -> 0.3 | Y22: =MAX(0,(X22-Annahmen!$B$140)/Annahmen!$B$141) -> 0 | Z22: =Y22*Annahmen!$B$137 -> 0 | AA22: =T22-U22-V22-W22-Z22 -> -562.78568 | AB22: =AB21+AA22 -> -1408.496 | AC22: =IF(AA22>0,1,0) -> 0 | AD22: =IF(AB22>=0,1,0) -> 0
